<?xml version="1.0"?>

<robot xmlns:xacro="http://www.ros.org/wiki/xacro" name="racecar">
  
  <xacro:property name="wheelbase" value="1.625" />
  <xacro:property name="width" value="1.0" />
  <xacro:property name="height" value="0.5" />
  <xacro:property name="ground_offset" value="0.2" />
  <xacro:property name="wheel_radius" value="0.25" />
  <xacro:property name="wheel_length" value="0.225" />
  <xacro:property name="laser_distance_from_base_link" value="1.375" />
  <xacro:property name="laser_height" value="0.25" />
  <xacro:property name="laser_radius" value="0.13" />

  <material name="black">
    <color rgba="0.2 0.2 0.2 1."/>
  </material>

  <material name="blue">
    <color rgba="0.3 0.57 1. 1."/>
  </material>

  <material name="dark">
    <color rgba="0.3 0.3 0.3 1.0"/>
  </material>

  <link name="base_footprint"/>

  <joint name="base_joint" type="fixed">
    <parent link="base_footprint"/>
    <child link="base_link" />
    <origin xyz="0 0 0.1675" rpy="0 0 0.0"/>
  </joint>

  <link name="base_link">
    <visual>
      <origin xyz="0.15 -0.325 -0.11" rpy="0 0 1.57"/>
      <geometry>
        <mesh filename="package://racecar_simulator/meshes/bases/mini_frame.stl" scale="0.005 0.005 0.005"/>
      </geometry>
      <material name="dark"/>
    </visual>

    <collision>
      <origin xyz="0.15 -0.325 -0.11" rpy="0 0 1.57"/>
      <geometry>
        <mesh filename="package://racecar_simulator/meshes/bases/mini_frame.stl" scale="0.005 0.005 0.005"/>
      </geometry>
    </collision>

    <inertial>
      <origin xyz="-0.5 0 0" rpy="0 0 0"/>
      <mass value="6.864548"/>
      <inertia ixx="0.043501359" ixy="-0.0002378829" ixz="0.00055802495"
               iyy="0.043097709" iyz="-0.00001771115"
               izz="0.073063635"/>
    </inertial>
  </link>

  <link name="center"/>

  <joint name="base_to_center" type="fixed">
    <parent link="base_link"/>
    <child link="center"/>
    <origin xyz="0.075 0 0"/>
  </joint>

  <link name="head"/>

  <joint name="base_to_head" type="fixed">
    <parent link="base_link"/>
    <child link="head"/>
    <origin xyz="0.15 0 0"/>
  </joint>

  <joint name="housing_joint" type="fixed">
    <parent link="base_link"/>
    <child link="housing_link" />
    <origin xyz="0 0 0" rpy="0 0 0.0"/>
  </joint>

  <link name="housing_link">
    <visual>
      <origin xyz="-0.14 0 -0.14" rpy="0 0 1.57"/>
      <geometry>
        <mesh filename="package://racecar_simulator/meshes/bases/r1mini housing lite 2.stl" scale="0.005 0.005 0.005"/>
      </geometry>
      <material name="blue"/>
    </visual>
    <collision>
      <origin xyz="-0.14 0 -0.14" rpy="0 0 1.57"/>
      <geometry>
        <mesh filename="package://racecar_simulator/meshes/bases/r1mini housing lite 2.stl" scale="0.005 0.005 0.005"/>
      </geometry>
    </collision>

    <inertial>
      <origin xyz="-0.5 0 0" rpy="0 0 0"/>
      <mass value="0.05"/>
      <inertia ixx="0.0043501359" ixy="-2.3788291e-06" ixz="5.5802495e-07"
               iyy="0.0043097709" iyz="-1.771115e-06"
               izz="0.00073063635"/>
    </inertial>
  </link>

  <joint name="imu_joint" type="fixed">
    <parent link="base_link"/>
    <child link="imu_link"/>
    <origin xyz="0.0 0 0.19" rpy="0 0 0"/>
  </joint>

  <link name="imu_link"/>

  <joint name="scan_joint" type="fixed">
    <parent link="base_link"/>
    <child link="base_scan"/>
    <origin xyz="0.0 0 0.35" rpy="0.0 0 3.14159"/>
  </joint>

  <link name="base_scan">
    <visual>
      <origin xyz="0 0 0.0" rpy="0 0 0"/>
      <geometry>
        <mesh filename="package://racecar_simulator/meshes/sensors/lds.stl" scale="0.005 0.005 0.005"/>
      </geometry>
      <material name="dark"/>
    </visual>

    <collision>
      <origin xyz="0.075 0 -0.0325" rpy="0 0 0"/>
      <geometry>
        <cylinder length="0.1575" radius="0.275"/>
      </geometry>
    </collision>

    <inertial>
      <mass value="0.25"/>
      <origin xyz="0 0 0"/>
      <inertia ixx="0.005" ixy="0.0" ixz="0.0"
               iyy="0.005" iyz="0.0"
               izz="0.005"/>
    </inertial>
  </link>

  <joint name="wheel_left_joint" type="continuous">
    <parent link="base_link"/>
    <child link="wheel_left_link"/>
    <origin xyz="0.0 0.48 0.0" rpy="0.0 0.0 0"/>
    <axis xyz="0 1 0"/>
  </joint>

  <link name="wheel_left_link">
    <visual>
      <origin xyz="-0.1675 -0.02 -0.1675" rpy="1.57 0 0"/>
      <geometry>
        <mesh filename="package://racecar_simulator/meshes/wheels/mini_tire.stl" scale="0.005 0.005 0.005"/>
      </geometry>
      <material name="dark"/>
    </visual>

    <collision>
      <origin xyz="-0.1675 -0.02 -0.1675" rpy="1.57 0 0"/>
      <geometry>
        <mesh filename="package://racecar_simulator/meshes/wheels/mini_tire.stl" scale="0.005 0.005 0.005"/>
      </geometry>
    </collision>

    <inertial>
      <origin xyz="0 0 0"/>
      <mass value="0.1424947"/>
      <inertia ixx="0.0000558779" ixy="-2.6429739e-10" ixz="-8.8782569e-08"
               iyy="0.00005596207" iyz="-7.2000535e-11"
               izz="0.00010356279"/>
    </inertial>
  </link>

  <joint name="wheel_right_joint" type="continuous">
    <parent link="base_link"/>
    <child link="wheel_right_link"/>
    <origin xyz="0.0 -0.48 0.0" rpy="0.0 0.0 0"/>
    <axis xyz="0 1 0"/>
  </joint>

  <link name="wheel_right_link">
    <visual>
      <origin xyz="-0.1675 0.02 0.1675" rpy="-1.57 0 0"/>
      <geometry>
        <mesh filename="package://racecar_simulator/meshes/wheels/mini_tire.stl" scale="0.005 0.005 0.005"/>
      </geometry>
      <material name="dark"/>
    </visual>
    <collision>
      <origin xyz="-0.1675 0.02 0.1675" rpy="-1.57 0 0"/>
      <geometry>
        <mesh filename="package://racecar_simulator/meshes/wheels/mini_tire.stl" scale="0.005 0.005 0.005"/>
      </geometry>
    </collision>
    <inertial>
      <origin xyz="0 0 0"/>
      <mass value="0.1424947"/>
      <inertia ixx="0.0000558779" ixy="-2.6429739e-10" ixz="-8.8782569e-08"
               iyy="0.00005596207" iyz="-7.2000535e-11"
               izz="0.00010356279"/>
    </inertial>
  </link>

  <joint name="caster_back_joint" type="fixed">
    <parent link="base_link"/>
    <child link="caster_back_link"/>
    <origin xyz="-0.6 0.0 -0.09" rpy="0 0 0"/>
  </joint>

  <link name="caster_back_link">
    <visual>
      <origin xyz="-0.08 -0.035 -0.08" rpy="0 0 0"/>
      <geometry>
        <mesh filename="package://racecar_simulator/meshes/wheels/mini_caster.stl" scale="0.005 0.005 0.005"/>
      </geometry>
      <material name="dark"/>
    </visual>
    <collision>
      <origin xyz="-0.08 -0.035 -0.08" rpy="0 0 0"/>
      <geometry>
        <mesh filename="package://racecar_simulator/meshes/wheels/mini_caster.stl" scale="0.005 0.005 0.005"/>
      </geometry>
    </collision>

    <inertial>
      <origin xyz="0 0 0"/>
      <mass value="0.025"/>
      <inertia ixx="0.005" ixy="0.0" ixz="0.0"
               iyy="0.005" iyz="0.0"
               izz="0.005"/>
    </inertial>
  </link>



</robot>
